<?xml version="1.0" encoding="UTF-8"?>
<testng-results skipped="0" failed="1" total="1" passed="0">
  <reporter-output>
  </reporter-output>
  <suite name="Default suite" duration-ms="9291" started-at="2017-05-31T18:23:48Z" finished-at="2017-05-31T18:23:57Z">
    <groups>
    </groups>
    <test name="Default test" duration-ms="9291" started-at="2017-05-31T18:23:48Z" finished-at="2017-05-31T18:23:57Z">
      <class name="test.NewTest">
        <test-method status="PASS" signature="beforeTest()[pri:0, instance:test.NewTest@27efef64]" name="beforeTest" is-config="true" duration-ms="5533" started-at="2017-05-31T14:23:48Z" finished-at="2017-05-31T14:23:53Z">
          <reporter-output>
          </reporter-output>
        </test-method> <!-- beforeTest -->
        <test-method status="FAIL" signature="test()[pri:0, instance:test.NewTest@27efef64]" name="test" duration-ms="3740" started-at="2017-05-31T14:23:53Z" finished-at="2017-05-31T14:23:57Z">
          <exception class="java.lang.AssertionError">
            <full-stacktrace>
              <![CDATA[java.lang.AssertionError
	at test.NewTest.test(NewTest.java:51)
	at sun.reflect.NativeMethodAccessorImpl.invoke0(Native Method)
	at sun.reflect.NativeMethodAccessorImpl.invoke(Unknown Source)
	at sun.reflect.DelegatingMethodAccessorImpl.invoke(Unknown Source)
	at java.lang.reflect.Method.invoke(Unknown Source)
	at org.testng.internal.MethodInvocationHelper.invokeMethod(MethodInvocationHelper.java:86)
	at org.testng.internal.Invoker.invokeMethod(Invoker.java:643)
	at org.testng.internal.Invoker.invokeTestMethod(Invoker.java:820)
	at org.testng.internal.Invoker.invokeTestMethods(Invoker.java:1128)
	at org.testng.internal.TestMethodWorker.invokeTestMethods(TestMethodWorker.java:129)
	at org.testng.internal.TestMethodWorker.run(TestMethodWorker.java:112)
	at org.testng.TestRunner.privateRun(TestRunner.java:782)
	at org.testng.TestRunner.run(TestRunner.java:632)
	at org.testng.SuiteRunner.runTest(SuiteRunner.java:366)
	at org.testng.SuiteRunner.runSequentially(SuiteRunner.java:361)
	at org.testng.SuiteRunner.privateRun(SuiteRunner.java:319)
	at org.testng.SuiteRunner.run(SuiteRunner.java:268)
	at org.testng.SuiteRunnerWorker.runSuite(SuiteRunnerWorker.java:52)
	at org.testng.SuiteRunnerWorker.run(SuiteRunnerWorker.java:86)
	at org.testng.TestNG.runSuitesSequentially(TestNG.java:1244)
	at org.testng.TestNG.runSuitesLocally(TestNG.java:1169)
	at org.testng.TestNG.run(TestNG.java:1064)
	at org.testng.remote.AbstractRemoteTestNG.run(AbstractRemoteTestNG.java:132)
	at org.testng.remote.RemoteTestNG.initAndRun(RemoteTestNG.java:230)
	at org.testng.remote.RemoteTestNG.main(RemoteTestNG.java:76)
]]>
            </full-stacktrace>
          </exception> <!-- java.lang.AssertionError -->
          <reporter-output>
          </reporter-output>
        </test-method> <!-- test -->
        <test-method status="PASS" signature="afterTest()[pri:0, instance:test.NewTest@27efef64]" name="afterTest" is-config="true" duration-ms="0" started-at="2017-05-31T14:23:57Z" finished-at="2017-05-31T14:23:57Z">
          <reporter-output>
          </reporter-output>
        </test-method> <!-- afterTest -->
      </class> <!-- test.NewTest -->
    </test> <!-- Default test -->
  </suite> <!-- Default suite -->
</testng-results>
